<sdf version='1.6'>
  <model name='catch_gripper'>
    <plugin name="gripper_plugin" filename="libgazebo_ros_catch_gripper.so">
    <ControlJointNames>
        catch_gripper::left_finger_joint,
        catch_gripper::right_finger_joint
      </ControlJointNames>
    </plugin>
    <link name='gripper_base'>
      <pose frame=''>0 0 0 0 -0 0</pose>
      <inertial>
        <pose frame=''>0.000721 9.8e-05 0.000307 0 -0 0</pose>
        <mass>0.471607</mass>
        <inertia>
          <ixx>0.000860606</ixx>
          <ixy>1.27043e-06</ixy>
          <ixz>7.56151e-07</ixz>
          <iyy>0.000242179</iyy>
          <iyz>3.32583e-07</iyz>
          <izz>0.00101242</izz>
        </inertia>
      </inertial>
      <collision name='gripper_base_collision'>
        <pose frame=''>0 0 0 0 -0 0</pose>
        <geometry>
          <mesh>
            <scale>1 1 1</scale>
            <uri>model://catch_gripper/meshes/gripper_base.STL</uri>
          </mesh>
        </geometry>
        <surface>
          <contact>
            <ode/>
          </contact>
          <friction>
            <ode/>
          </friction>
        </surface>
      </collision>
      <visual name='gripper_base_visual'>
        <pose frame=''>0 0 0 0 -0 0</pose>
        <geometry>
          <mesh>
            <scale>1 1 1</scale>
            <uri>model://catch_gripper/meshes/gripper_base.STL</uri>
          </mesh>
        </geometry>
        <material>
          <script>
            <name>Gazebo/Black</name>
            <uri>file://catch_gripper/materials/scripts/gazebo.material</uri>
          </script>
        </material>
      </visual>
      <gravity>1</gravity>
      <velocity_decay/>
    </link>
    <link name='left_finger'>
      <pose frame=''>0 -0.044885 0.04 0 -0 0</pose>
      <inertial>
        <pose frame=''>-0.000105 0.008232 0.030488 0 -0 0</pose>
        <mass>0.140873</mass>
        <inertia>
          <ixx>0.000208231</ixx>
          <ixy>4.76664e-07</ixy>
          <ixz>-7.69205e-07</ixz>
          <iyy>0.000192629</iyy>
          <iyz>-3.30016e-05</iyz>
          <izz>3.72131e-05</izz>
        </inertia>
      </inertial>
      <collision name='left_finger_collision'>
        <pose frame=''>0 0 0 0 -0 0</pose>
        <geometry>
          <mesh>
            <scale>1 1 1</scale>
            <uri>model://catch_gripper/meshes/left_finger.STL</uri>
          </mesh>
        </geometry>
        <surface>
          <contact>
            <ode/>
          </contact>
          <friction>
            <ode/>
          </friction>
        </surface>
      </collision>
      <collision name='left_finger_fixed_joint_lump__left_contact_collision_1'>
        <pose frame=''>0 0.018 0.092 0 -0 0</pose>
        <geometry>
          <box>
            <size>0.025 0.003 0.03</size>
          </box>
        </geometry>
        <surface>
          <contact>
            <ode>
              <kp>1e+06</kp>
              <kd>1</kd>
            </ode>
          </contact>
          <friction>
            <ode>
              <mu>10000</mu>
              <mu2>10000</mu2>
            </ode>
          </friction>
        </surface>
      </collision>
      <visual name='left_finger_visual'>
        <pose frame=''>0 0 0 0 -0 0</pose>
        <geometry>
          <mesh>
            <scale>1 1 1</scale>
            <uri>model://catch_gripper/meshes/left_finger.STL</uri>
          </mesh>
        </geometry>
        <material>
          <script>
            <name>Gazebo/Grey</name>
            <uri>file://catch_gripper/materials/scripts/gazebo.material</uri>
          </script>
        </material>
      </visual>
      <velocity_decay/>
      <gravity>1</gravity>
      <velocity_decay/>
    </link>
    <joint name='left_finger_joint' type='prismatic'>
      <child>left_finger</child>
      <parent>gripper_base</parent>
      <axis>
        <xyz>0 1 0</xyz>
        <limit>
          <lower>0</lower>
          <upper>0.025425</upper>
          <effort>12206.2</effort>
          <velocity>8.72665</velocity>
        </limit>
        <dynamics>
          <spring_reference>0</spring_reference>
          <spring_stiffness>0</spring_stiffness>
        </dynamics>
        <use_parent_model_frame>1</use_parent_model_frame>
      </axis>
    </joint>
    <link name='right_finger'>
      <pose frame=''>0 0.044885 0.04 0 -0 0</pose>
      <inertial>
        <pose frame=''>0.000197 -0.007215 0.028165 0 -0 0</pose>
        <mass>0.135519</mass>
        <inertia>
          <ixx>0.000189728</ixx>
          <ixy>4.05432e-07</ixy>
          <ixz>1.17915e-06</ixz>
          <iyy>0.000179898</iyy>
          <iyz>2.713e-05</iyz>
          <izz>3.58456e-05</izz>
        </inertia>
      </inertial>
      <collision name='right_finger_collision'>
        <pose frame=''>0 0 0 0 -0 0</pose>
        <geometry>
          <mesh>
            <scale>1 1 1</scale>
            <uri>model://catch_gripper/meshes/right_finger.STL</uri>
          </mesh>
        </geometry>
        <surface>
          <contact>
            <ode/>
          </contact>
          <friction>
            <ode/>
          </friction>
        </surface>
      </collision>
      <collision name='right_finger_fixed_joint_lump__right_contact_collision_1'>
        <pose frame=''>0 -0.018 0.092 0 -0 0</pose>
        <geometry>
          <box>
            <size>0.025 0.003 0.03</size>
          </box>
        </geometry>
        <surface>
          <contact>
            <ode>
              <kp>1e+06</kp>
              <kd>1</kd>
            </ode>
          </contact>
          <friction>
            <ode>
              <mu>10000</mu>
              <mu2>10000</mu2>
            </ode>
          </friction>
        </surface>
      </collision>
      <visual name='right_finger_visual'>
        <pose frame=''>0 0 0 0 -0 0</pose>
        <geometry>
          <mesh>
            <scale>1 1 1</scale>
            <uri>model://catch_gripper/meshes/right_finger.STL</uri>
          </mesh>
        </geometry>
        <material>
          <script>
            <name>Gazebo/Grey</name>
            <uri>file://catch_gripper/materials/scripts/gazebo.material</uri>
          </script>
        </material>
      </visual>
      <velocity_decay/>
      <gravity>1</gravity>
      <velocity_decay/>
    </link>
    <joint name='right_finger_joint' type='prismatic'>
      <child>right_finger</child>
      <parent>gripper_base</parent>
      <axis>
        <xyz>0 -1 0</xyz>
        <limit>
          <lower>0</lower>
          <upper>0.025425</upper>
          <effort>23945.2</effort>
          <velocity>8.72665</velocity>
        </limit>
        <dynamics>
          <spring_reference>0</spring_reference>
          <spring_stiffness>0</spring_stiffness>
        </dynamics>
        <use_parent_model_frame>1</use_parent_model_frame>
      </axis>
    </joint>
  </model>
</sdf>
