<?xml version="1.0" ?>
<sdf version='1.6'>
  <model name='rr6'>
    <link name='table_link'>
      <pose frame=''>0 0 0.6 0 -0 0</pose>
      <inertial>
        <pose frame=''>-0.000409 -0 0.000507 0 -0 0</pose>
        <mass>1005.14</mass>
        <inertia>
          <ixx>74.2514</ixx>
          <ixy>1.43459e-06</ixy>
          <ixz>0.0385426</ixz>
          <iyy>74.3223</iyy>
          <iyz>6.71673e-06</iyz>
          <izz>106.764</izz>
        </inertia>
      </inertial>
      <collision name='table_link_collision'>
        <pose frame=''>0 0 -0.25 0 -0 0</pose>
        <geometry>
          <box>
            <size>0.8 0.8 0.5</size>
          </box>
        </geometry>
        <surface>
          <contact>
            <ode/>
          </contact>
          <friction>
            <ode/>
          </friction>
        </surface>
      </collision>
      <collision name='table_link_fixed_joint_lump__rr6_link0_collision_1'>
        <pose frame=''>0 0 0 0 -0 0</pose>
        <geometry>
          <mesh>
            <scale>1 1 1</scale>
            <uri>model://rr6/meshes/rr6_link0.STL</uri>
          </mesh>
        </geometry>
        <surface>
          <contact>
            <ode/>
          </contact>
          <friction>
            <ode/>
          </friction>
        </surface>
      </collision>
      <visual name='table_link_visual'>
        <pose frame=''>0 0 -0.3 0 -0 0</pose>
        <geometry>
          <box>
            <size>0.8 0.8 0.6</size>
          </box>
        </geometry>
        <material>
          <script>
            <name>Gazebo/Grey</name>
            <uri>file://rr6/materials/scripts/gazebo.material</uri>
          </script>
        </material>
      </visual>
      <visual name='table_link_fixed_joint_lump__rr6_link0_visual_1'>
        <pose frame=''>0 0 0 0 -0 0</pose>
        <geometry>
          <mesh>
            <scale>1 1 1</scale>
            <uri>model://rr6/meshes/rr6_link0.STL</uri>
          </mesh>
        </geometry>
        <material>
          <script>
            <name>Gazebo/Orange</name>
            <uri>file://rr6/materials/scripts/gazebo.material</uri>
          </script>
        </material>
      </visual>
      <velocity_decay/>
      <self_collide>0</self_collide>
      <gravity>1</gravity>
      <velocity_decay/>
    </link>
    <joint name='fixed1' type='fixed'>
      <child>table_link</child>
      <parent>world</parent>
    </joint>
    <link name='rr6_link1'>
      <pose frame=''>0 0 0.96989 0 -0 0</pose>
      <inertial>
        <pose frame=''>0.023895 -0.002519 -0.068699 0 -0 0</pose>
        <mass>2.00634</mass>
        <inertia>
          <ixx>0.0143834</ixx>
          <ixy>0.000402838</ixy>
          <ixz>-0.00291028</ixz>
          <iyy>0.0135733</iyy>
          <iyz>0.000283167</iyz>
          <izz>0.0145487</izz>
        </inertia>
      </inertial>
      <collision name='rr6_link1_collision'>
        <pose frame=''>0 0 0 0 -0 0</pose>
        <geometry>
          <mesh>
            <scale>1 1 1</scale>
            <uri>model://rr6/meshes/rr6_link1.STL</uri>
          </mesh>
        </geometry>
        <surface>
          <contact>
            <ode/>
          </contact>
          <friction>
            <ode/>
          </friction>
        </surface>
      </collision>
      <visual name='rr6_link1_visual'>
        <pose frame=''>0 0 0 0 -0 0</pose>
        <geometry>
          <mesh>
            <scale>1 1 1</scale>
            <uri>model://rr6/meshes/rr6_link1.STL</uri>
          </mesh>
        </geometry>
        <material>
          <script>
            <name>Gazebo/White</name>
            <uri>file://rr6/materials/scripts/gazebo.material</uri>
          </script>
        </material>
      </visual>
      <gravity>1</gravity>
      <velocity_decay/>
    </link>
    <joint name='rr6_joint1' type='revolute'>
      <child>rr6_link1</child>
      <parent>table_link</parent>
      <axis>
        <xyz>0 0 1</xyz>
        <limit>
          <lower>-3.14159</lower>
          <upper>3.14159</upper>
          <effort>635993</effort>
          <velocity>8.72665</velocity>
        </limit>
        <dynamics>
          <spring_reference>0</spring_reference>
          <spring_stiffness>0</spring_stiffness>
        </dynamics>
        <use_parent_model_frame>1</use_parent_model_frame>
      </axis>
    </joint>
    <link name='rr6_link2'>
      <pose frame=''>0.0884 0 0.96989 1.57079 -1.57079 3.14159</pose>
      <inertial>
        <pose frame=''>0.101428 0.000333 0.002303 0 -0 0</pose>
        <mass>2.5441</mass>
        <inertia>
          <ixx>0.0123848</ixx>
          <ixy>6.29791e-05</ixy>
          <ixz>5.21448e-05</ixz>
          <iyy>0.0314854</iyy>
          <iyz>1.28638e-05</iyz>
          <izz>0.0269248</izz>
        </inertia>
      </inertial>
      <collision name='rr6_link2_collision'>
        <pose frame=''>0 0 0 0 -0 0</pose>
        <geometry>
          <mesh>
            <scale>1 1 1</scale>
            <uri>model://rr6/meshes/rr6_link2.STL</uri>
          </mesh>
        </geometry>
        <surface>
          <contact>
            <ode/>
          </contact>
          <friction>
            <ode/>
          </friction>
        </surface>
      </collision>
      <visual name='rr6_link2_visual'>
        <pose frame=''>0 0 0 0 -0 0</pose>
        <geometry>
          <mesh>
            <scale>1 1 1</scale>
            <uri>model://rr6/meshes/rr6_link2.STL</uri>
          </mesh>
        </geometry>
        <material>
          <script>
            <name>Gazebo/Orange</name>
            <uri>file://rr6/materials/scripts/gazebo.material</uri>
          </script>
        </material>
      </visual>
      <gravity>1</gravity>
      <velocity_decay/>
    </link>
    <joint name='rr6_joint2' type='revolute'>
      <child>rr6_link2</child>
      <parent>rr6_link1</parent>
      <axis>
        <xyz>-0 1 -0</xyz>
        <limit>
          <lower>-0.890118</lower>
          <upper>2.19999</upper>
          <effort>460906</effort>
          <velocity>8.72665</velocity>
        </limit>
        <dynamics>
          <spring_reference>0</spring_reference>
          <spring_stiffness>0</spring_stiffness>
        </dynamics>
        <use_parent_model_frame>1</use_parent_model_frame>
      </axis>
    </joint>
    <link name='rr6_link3'>
      <pose frame=''>0.0884 0 1.22989 1.57079 -1.57079 3.14159</pose>
      <inertial>
        <pose frame=''>-0.008125 0.011638 0.001883 0 -0 0</pose>
        <mass>1.17218</mass>
        <inertia>
          <ixx>0.00438154</ixx>
          <ixy>-1.41093e-05</ixy>
          <ixz>-2.08226e-05</ixz>
          <iyy>0.00455094</iyy>
          <iyz>-3.32515e-05</iyz>
          <izz>0.00492817</izz>
        </inertia>
      </inertial>
      <collision name='rr6_link3_collision'>
        <pose frame=''>0 0 0 0 -0 0</pose>
        <geometry>
          <mesh>
            <scale>1 1 1</scale>
            <uri>model://rr6/meshes/rr6_link3.STL</uri>
          </mesh>
        </geometry>
        <surface>
          <contact>
            <ode/>
          </contact>
          <friction>
            <ode/>
          </friction>
        </surface>
      </collision>
      <visual name='rr6_link3_visual'>
        <pose frame=''>0 0 0 0 -0 0</pose>
        <geometry>
          <mesh>
            <scale>1 1 1</scale>
            <uri>model://rr6/meshes/rr6_link3.STL</uri>
          </mesh>
        </geometry>
        <material>
          <script>
            <name>Gazebo/White</name>
            <uri>file://rr6/materials/scripts/gazebo.material</uri>
          </script>
        </material>
      </visual>
      <gravity>1</gravity>
      <velocity_decay/>
    </link>
    <joint name='rr6_joint3' type='revolute'>
      <child>rr6_link3</child>
      <parent>rr6_link2</parent>
      <axis>
        <xyz>-0 1 -0</xyz>
        <limit>
          <lower>-3.59992</lower>
          <upper>0.59987</upper>
          <effort>238892</effort>
          <velocity>8.72665</velocity>
        </limit>
        <dynamics>
          <spring_reference>0</spring_reference>
          <spring_stiffness>0</spring_stiffness>
        </dynamics>
        <use_parent_model_frame>1</use_parent_model_frame>
      </axis>
    </joint>
    <link name='rr6_link4'>
      <pose frame=''>0.3294 0 1.22989 0 -1.57079 3.14159</pose>
      <inertial>
        <pose frame=''>0.004664 0.004229 -0.088618 0 -0 0</pose>
        <mass>1.04031</mass>
        <inertia>
          <ixx>0.00527621</ixx>
          <ixy>5.38548e-05</ixy>
          <ixz>0.000185559</ixz>
          <iyy>0.00518564</iyy>
          <iyz>-0.00018345</iyz>
          <izz>0.00282202</izz>
        </inertia>
      </inertial>
      <collision name='rr6_link4_collision'>
        <pose frame=''>0 0 0 0 -0 0</pose>
        <geometry>
          <mesh>
            <scale>1 1 1</scale>
            <uri>model://rr6/meshes/rr6_link4.STL</uri>
          </mesh>
        </geometry>
        <surface>
          <contact>
            <ode/>
          </contact>
          <friction>
            <ode/>
          </friction>
        </surface>
      </collision>
      <visual name='rr6_link4_visual'>
        <pose frame=''>0 0 0 0 -0 0</pose>
        <geometry>
          <mesh>
            <scale>1 1 1</scale>
            <uri>model://rr6/meshes/rr6_link4.STL</uri>
          </mesh>
        </geometry>
        <material>
          <script>
            <name>Gazebo/Orange</name>
            <uri>file://rr6/materials/scripts/gazebo.material</uri>
          </script>
        </material>
      </visual>
      <gravity>1</gravity>
      <velocity_decay/>
    </link>
    <joint name='rr6_joint4' type='revolute'>
      <child>rr6_link4</child>
      <parent>rr6_link3</parent>
      <axis>
        <xyz>1 0 -0</xyz>
        <limit>
          <lower>-3.14159</lower>
          <upper>3.14159</upper>
          <effort>136599</effort>
          <velocity>8.72665</velocity>
        </limit>
        <dynamics>
          <spring_reference>0</spring_reference>
          <spring_stiffness>0</spring_stiffness>
        </dynamics>
        <use_parent_model_frame>1</use_parent_model_frame>
      </axis>
    </joint>
    <link name='rr6_link5'>
      <pose frame=''>0.3294 0 1.22989 1.57079 -1.57079 3.14159</pose>
      <inertial>
        <pose frame=''>-1e-05 0.014655 -0.001176 0 -0 0</pose>
        <mass>0.49536</mass>
        <inertia>
          <ixx>0.000610482</ixx>
          <ixy>2.41428e-07</ixy>
          <ixz>1.50483e-07</ixz>
          <iyy>0.000428578</iyy>
          <iyz>-8.79101e-06</iyz>
          <izz>0.000740887</izz>
        </inertia>
      </inertial>
      <collision name='rr6_link5_collision'>
        <pose frame=''>0 0 0 0 -0 0</pose>
        <geometry>
          <mesh>
            <scale>1 1 1</scale>
            <uri>model://rr6/meshes/rr6_link5.STL</uri>
          </mesh>
        </geometry>
        <surface>
          <contact>
            <ode/>
          </contact>
          <friction>
            <ode/>
          </friction>
        </surface>
      </collision>
      <visual name='rr6_link5_visual'>
        <pose frame=''>0 0 0 0 -0 0</pose>
        <geometry>
          <mesh>
            <scale>1 1 1</scale>
            <uri>model://rr6/meshes/rr6_link5.STL</uri>
          </mesh>
        </geometry>
        <material>
          <script>
            <name>Gazebo/White</name>
            <uri>file://rr6/materials/scripts/gazebo.material</uri>
          </script>
        </material>
      </visual>
      <gravity>1</gravity>
      <velocity_decay/>
    </link>
    <joint name='rr6_joint5' type='revolute'>
      <child>rr6_link5</child>
      <parent>rr6_link4</parent>
      <axis>
        <xyz>-0 1 -0</xyz>
        <limit>
          <lower>-1.74533</lower>
          <upper>1.74533</upper>
          <effort>45815.3</effort>
          <velocity>8.72665</velocity>
        </limit>
        <dynamics>
          <spring_reference>0</spring_reference>
          <spring_stiffness>0</spring_stiffness>
        </dynamics>
        <use_parent_model_frame>1</use_parent_model_frame>
      </axis>
    </joint>
    <link name='rr6_link6'>
      <pose frame=''>0.4184 0 1.22989 0 -1.57079 3.14159</pose>
      <inertial>
        <pose frame=''>0 -4.9e-05 -0.006095 0 -0 0</pose>
        <mass>0.0296445</mass>
        <inertia>
          <ixx>9.71075e-06</ixx>
          <ixy>-1.16765e-13</ixy>
          <ixz>4.13768e-15</ixz>
          <iyy>9.75718e-06</iyy>
          <iyz>-7.41228e-09</iyz>
          <izz>1.83481e-05</izz>
        </inertia>
      </inertial>
      <collision name='rr6_link6_collision'>
        <pose frame=''>0 0 0 0 -0 0</pose>
        <geometry>
          <mesh>
            <scale>1 1 1</scale>
            <uri>model://rr6/meshes/rr6_link6.STL</uri>
          </mesh>
        </geometry>
        <surface>
          <contact>
            <ode/>
          </contact>
          <friction>
            <ode/>
          </friction>
        </surface>
      </collision>
      <visual name='rr6_link6_visual'>
        <pose frame=''>0 0 0 0 -0 0</pose>
        <geometry>
          <mesh>
            <scale>1 1 1</scale>
            <uri>model://rr6/meshes/rr6_link6.STL</uri>
          </mesh>
        </geometry>
        <material>
          <script>
            <name>Gazebo/Orange</name>
            <uri>file://rr6/materials/scripts/gazebo.material</uri>
          </script>
        </material>
      </visual>
      <gravity>1</gravity>
      <velocity_decay/>
    </link>
    <joint name='rr6_joint6' type='revolute'>
      <child>rr6_link6</child>
      <parent>rr6_link5</parent>
      <axis>
        <xyz>1 0 -0</xyz>
        <limit>
          <lower>-6.28319</lower>
          <upper>6.28319</upper>
          <effort>2586.97</effort>
          <velocity>8.72665</velocity>
        </limit>
        <dynamics>
          <spring_reference>0</spring_reference>
          <spring_stiffness>0</spring_stiffness>
        </dynamics>
        <use_parent_model_frame>1</use_parent_model_frame>
      </axis>
    </joint>
    <static>0</static>
    <plugin name='gazebo_ros_control' filename='libgazebo_ros_robot_control.so'>
      <ConfigFile>/home/zhyp/.gazebo/models/rr6/config.yaml</ConfigFile>
    </plugin>
  </model>
</sdf>
